Workbook

Sheet Генеральная совокупность
A1: Индекс | B1: Значение
A2: 1 | B2: 10
A3: 2 | B3: 10
A4: 3 | B4: 7
A5: 4 | B5: 8
A6: 5 | B6: 11
A7: 6 | B7: 7
A8: 7 | B8: 9
A9: 8 | B9: 6
A10: 9 | B10: 8
A11: 10 | B11: 6
A12: 11 | B12: 6
A13: 12 | B13: 12
... A401: 400 | B401: 6

Sheet Подвыборки
A1: n = 10 (индекс) | B1: n = 10 (Значение) | C1: Вар.ряд индекс | D1: Значение | F1: n = 25 (индекс) | G1: n = 25 (Значение) | H1: Вар.ряд индекс | I1: Значение | K1: n = 50 (индекс) | L1: n = 50 (Значение) | M1: Вар.ряд индекс | N1: Значение | P1: n = 100 (индекс) | Q1: n = 100 (Значение) | R1: Вар.ряд индекс | S1: Значение | U1: n = 200 (индекс) | V1: n = 200 (Значение) | W1: Вар.ряд индекс | X1: Значение
A2: 392 | B2: 17 | C2: 223 | D2: 5 | F2: 352 | G2: 5 | H2: 88 | I2: 4 | K2: 375 | L2: 4 | M2: 84 | N2: 2 | P2: 19 | Q2: 8 | R2: 84 | S2: 2 | U2: 37 | V2: 12 | W2: 202 | X2: 1
A3: 294 | B3: 8 | C3: 294 | D3: 8 | F3: 229 | G3: 9 | H3: 97 | I3: 4 | K3: 43 | L3: 15 | M3: 375 | N3: 4 | P3: 396 | Q3: 11 | R3: 31 | S3: 3 | U3: 378 | V3: 6 | W3: 130 | X3: 1
A4: 350 | B4: 9 | C4: 124 | D4: 8 | F4: 147 | G4: 12 | H4: 235 | I4: 4 | K4: 268 | L4: 9 | M4: 208 | N4: 4 | P4: 354 | Q4: 4 | R4: 87 | S4: 3 | U4: 365 | V4: 11 | W4: 254 | X4: 1
A5: 343 | B5: 12 | C5: 350 | D5: 9 | F5: 2 | G5: 10 | H5: 352 | I5: 5 | K5: 300 | L5: 9 | M5: 72 | N5: 4 | P5: 119 | Q5: 7 | R5: 354 | S5: 4 | U5: 97 | V5: 4 | W5: 369 | X5: 2
A6: 379 | B6: 12 | C6: 343 | D6: 12 | F6: 255 | G6: 12 | H6: 239 | I6: 5 | K6: 67 | L6: 5 | M6: 97 | N6: 4 | P6: 31 | Q6: 3 | R6: 194 | S6: 4 | U6: 278 | V6: 8 | W6: 209 | X6: 3
A7: 176 | B7: 13 | C7: 379 | D7: 12 | F7: 351 | G7: 8 | H7: 55 | I7: 5 | K7: 298 | L7: 10 | M7: 301 | N7: 4 | P7: 152 | Q7: 6 | R7: 236 | S7: 4 | U7: 147 | V7: 12 | W7: 394 | X7: 3
A8: 186 | B8: 14 | C8: 176 | D8: 13 | F8: 239 | G8: 5 | H8: 203 | I8: 6 | K8: 84 | L8: 2 | M8: 67 | N8: 5 | P8: 79 | Q8: 14 | R8: 148 | S8: 4 | U8: 163 | V8: 8 | W8: 356 | X8: 3
A9: 96 | B9: 13 | C9: 96 | D9: 13 | F9: 7 | G9: 9 | H9: 382 | I9: 6 | K9: 291 | L9: 13 | M9: 51 | N9: 5 | P9: 183 | Q9: 8 | R9: 316 | S9: 4 | U9: 36 | V9: 7 | W9: 129 | X9: 3
A10: 223 | B10: 5 | C10: 186 | D10: 14 | F10: 176 | G10: 13 | H10: 139 | I10: 6 | K10: 188 | L10: 13 | M10: 23 | N10: 5 | P10: 13 | Q10: 10 | R10: 317 | S10: 4 | U10: 17 | V10: 6 | W10: 327 | X10: 3
A11: 124 | B11: 8 | C11: 392 | D11: 17 | F11: 156 | G11: 7 | H11: 95 | I11: 6 | K11: 208 | L11: 4 | M11: 309 | N11: 5 | P11: 359 | Q11: 10 | R11: 353 | S11: 4 | U11: 397 | V11: 13 | W11: 31 | X11: 3
F12: 203 | G12: 6 | H12: 156 | I12: 7 | K12: 111 | L12: 9 | M12: 82 | N12: 5 | P12: 305 | Q12: 10 | R12: 260 | S12: 5 | U12: 158 | V12: 6 | W12: 97 | X12: 4
F13: 128 | G13: 13 | H13: 242 | I13: 7 | K13: 51 | L13: 5 | M13: 118 | N13: 5 | P13: 241 | Q13: 11 | R13: 323 | S13: 5 | U13: 298 | V13: 10 | W13: 194 | X13: 4
F14: 292 | G14: 11 | H14: 190 | I14: 7 | K14: 362 | L14: 8 | M14: 171 | N14: 6 | P14: 263 | Q14: 6 | R14: 257 | S14: 5 | U14: 146 | V14: 6 | W14: 148 | X14: 4
F15: 382 | G15: 6 | H15: 77 | I15: 7 | K15: 98 | L15: 9 | M15: 344 | N15: 6 | P15: 194 | Q15: 4 | R15: 58 | S15: 5 | U15: 389 | V15: 14 | W15: 81 | X15: 4
F16: 88 | G16: 4 | H16: 351 | I16: 8 | K16: 150 | L16: 11 | M16: 152 | N16: 6 | P16: 225 | Q16: 10 | R16: 118 | S16: 5 | U16: 357 | V16: 6 | W16: 353 | X16: 4
F17: 242 | G17: 7 | H17: 277 | I17: 8 | K17: 23 | L17: 5 | M17: 199 | N17: 6 | P17: 346 | Q17: 8 | R17: 223 | S17: 5 | U17: 293 | V17: 15 | W17: 316 | X17: 4
F18: 55 | G18: 5 | H18: 362 | I18: 8 | K18: 124 | L18: 8 | M18: 80 | N18: 6 | P18: 169 | Q18: 8 | R18: 226 | S18: 5 | U18: 209 | V18: 3 | W18: 358 | X18: 4
F19: 139 | G19: 6 | H19: 229 | I19: 9 | K19: 216 | L19: 10 | M19: 92 | N19: 7 | P19: 197 | Q19: 10 | R19: 349 | S19: 5 | U19: 154 | V19: 6 | W19: 371 | X19: 4
F20: 97 | G20: 4 | H20: 7 | I20: 9 | K20: 171 | L20: 6 | M20: 362 | N20: 8 | P20: 68 | Q20: 18 | R20: 55 | S20: 5 | U20: 190 | V20: 7 | W20: 310 | X20: 5
F21: 277 | G21: 8 | H21: 2 | I21: 10 | K21: 241 | L21: 11 | M21: 124 | N21: 8 | P21: 251 | Q21: 11 | R21: 336 | S21: 5 | U21: 47 | V21: 6 | W21: 76 | X21: 5
F22: 95 | G22: 6 | H22: 292 | I22: 11 | K22: 309 | L22: 5 | M22: 136 | N22: 8 | P22: 236 | Q22: 4 | R22: 318 | S22: 5 | U22: 262 | V22: 8 | W22: 309 | X22: 5
F23: 235 | G23: 4 | H23: 147 | I23: 12 | K23: 168 | L23: 16 | M23: 185 | N23: 8 | P23: 260 | Q23: 5 | R23: 265 | S23: 5 | U23: 216 | V23: 10 | W23: 349 | X23: 5
... F26: 77 | G26: 7 | H26: 128 | I26: 13 | K26: 344 | L26: 6 | M26: 27 | N26: 8 | P26: 78 | Q26: 10 | R26: 310 | S26: 5 | U26: 361 | V26: 9 | W26: 259 | X26: 5
K27: 152 | L27: 6 | M27: 278 | N27: 8 | P27: 316 | Q27: 4 | R27: 152 | S27: 6 | U27: 173 | V27: 7 | W27: 223 | X27: 5
K28: 136 | L28: 8 | M28: 215 | N28: 8 | P28: 331 | Q28: 10 | R28: 263 | S28: 6 | U28: 30 | V28: 7 | W28: 51 | X28: 5
K29: 108 | L29: 9 | M29: 268 | N29: 9 | P29: 367 | Q29: 9 | R29: 279 | S29: 6 | U29: 315 | V29: 7 | W29: 118 | X29: 5
K30: 185 | L30: 8 | M30: 300 | N30: 9 | P30: 190 | Q30: 7 | R30: 17 | S30: 6 | U30: 394 | V30: 3 | W30: 363 | X30: 5
K31: 214 | L31: 8 | M31: 111 | N31: 9 | P31: 279 | Q31: 6 | R31: 400 | S31: 6 | U31: 310 | V31: 5 | W31: 325 | X31: 5
K32: 118 | L32: 5 | M32: 98 | N32: 9 | P32: 339 | Q32: 8 | R32: 180 | S32: 6 | U32: 219 | V32: 8 | W32: 226 | X32: 5
K33: 169 | L33: 8 | M33: 108 | N33: 9 | P33: 17 | Q33: 6 | R33: 144 | S33: 6 | U33: 188 | V33: 13 | W33: 342 | X33: 5
K34: 68 | L34: 18 | M34: 373 | N34: 9 | P34: 317 | Q34: 4 | R34: 53 | S34: 6 | U34: 241 | V34: 11 | W34: 239 | X34: 5
K35: 27 | L35: 8 | M35: 250 | N35: 9 | P35: 323 | Q35: 5 | R35: 357 | S35: 6 | U35: 210 | V35: 8 | W35: 257 | X35: 5
K36: 20 | L36: 10 | M36: 38 | N36: 9 | P36: 308 | Q36: 12 | R36: 382 | S36: 6 | U36: 356 | V36: 3 | W36: 378 | X36: 6
K37: 258 | L37: 10 | M37: 298 | N37: 10 | P37: 214 | Q37: 8 | R37: 22 | S37: 6 | U37: 76 | V37: 5 | W37: 17 | X37: 6
K38: 373 | L38: 9 | M38: 216 | N38: 10 | P38: 1 | Q38: 10 | R38: 119 | S38: 7 | U38: 245 | V38: 10 | W38: 158 | X38: 6
... K51: 106 | L51: 10 | M51: 68 | N51: 18 | P51: 201 | Q51: 8 | R51: 339 | S51: 8 | U51: 309 | V51: 5 | W51: 80 | X51: 6
P52: 132 | Q52: 10 | R52: 214 | S52: 8 | U52: 20 | V52: 10 | W52: 63 | X52: 6
P53: 223 | Q53: 5 | R53: 276 | S53: 8 | U53: 349 | V53: 5 | W53: 171 | X53: 6
P54: 372 | Q54: 11 | R54: 124 | S54: 8 | U54: 109 | V54: 10 | W54: 26 | X54: 6
...

Sheet Статистики
B1: Объём | C1: Среднее | D1: Медиана | E1: Мода | F1: Дисперсия | G1: СКО | H1: Ст. ошибка | I1: 95% ДИ (для среднего) | J1: Левая граница 95% ДИ (для среднего) | K1: Правая граница 95% ДИ (для среднего) | L1: 95% ДИ (для дисперсии) | M1: Левая граница 95% ДИ (для дисперсии) | N1: Правая граница 95% ДИ (для дисперсии)
A2: Генеральная совокупность | B2: 400 | C2: =AVERAGE('Генеральная совокупность'!B:B) -> 7.9875 | D2: =MEDIAN('Генеральная совокупность'!B:B) -> 8 | E2: =_xlfn.MODE.SNGL('Генеральная совокупность'!B:B) -> 6 | F2: =_xlfn.VAR.P('Генеральная совокупность'!B:B) -> 8.2773438 | G2: =SQRT(F2) -> 2.8770373 | H2: =_xlfn.STDEV.P('Генеральная совокупность'!B:B)/SQRT(Статистики!B2) -> 0.14385187 | I2: =_xlfn.CONFIDENCE.T(0.05,_xlfn.STDEV.P('Генеральная совокупность'!B:B),Статистики!B2) -> 0.28280231 | J2: =C2-I2 -> 7.7046977 | K2: =C2+I2 -> 8.2703023 | L2: =(B2-1)*F2/_xlfn.CHISQ.INV.RT(0.975,B2-1)-(B2-1)*F2/_xlfn.CHISQ.INV.RT(0.025,B2-1) -> 2.3187322 | M2: =(B2-1)*F2/_xlfn.CHISQ.INV.RT(0.025,B2-1) -> 7.2389276 | N2: =(B2-1)*F2/_xlfn.CHISQ.INV.RT(0.975,B2-1) -> 9.5576598
A3: 1 Выборка (n = 10) | B3: 10 | C3: =AVERAGE(Подвыборки!B:B) -> 11.1 | D3: =MEDIAN(Подвыборки!D:D) -> 12 | E3: =_xlfn.MODE.SNGL(Подвыборки!B:B) -> 8 | F3: =_xlfn.VAR.S(Подвыборки!B:B) -> 12.544444 | G3: =SQRT(F3) -> 3.5418137 | H3: =_xlfn.STDEV.S(Подвыборки!B:B)/SQRT(Статистики!B3) -> 1.1200198 | I3: =_xlfn.CONFIDENCE.T(0.05,_xlfn.STDEV.S(Подвыборки!B:B),Статистики!B3) -> 2.5336609 | J3: =C3-I3 -> 8.5663391 | K3: =C3+I3 -> 13.633661 | L3: =(B3-1)*F3/_xlfn.CHISQ.INV.RT(0.975,B3-1)-(B3-1)*F3/_xlfn.CHISQ.INV.RT(0.025,B3-1) -> 35.87379 | M3: =(B3-1)*F3/_xlfn.CHISQ.INV.RT(0.025,B3-1) -> 5.9349933 | N3: =(B3-1)*F3/_xlfn.CHISQ.INV.RT(0.975,B3-1) -> 41.808784
A4: 2 Выборка (n = 25) | B4: 25 | C4: =AVERAGE(Подвыборки!G:G) -> 7.68 | D4: =MEDIAN(Подвыборки!I:I) -> 7 | E4: =_xlfn.MODE.SNGL(Подвыборки!G:G) -> 7 | F4: =_xlfn.VAR.S(Подвыборки!G:G) -> 7.8933333 | G4: =SQRT(F4) -> 2.8095077 | H4: =_xlfn.STDEV.S(Подвыборки!G:G)/SQRT(Статистики!B4) -> 0.56190153 | I4: =_xlfn.CONFIDENCE.T(0.05,_xlfn.STDEV.S(Подвыборки!G:G),Статистики!B4) -> 1.1597078 | J4: =C4-I4 -> 6.5202922 | K4: =C4+I4 -> 8.8397078 | L4: =(B4-1)*F4/_xlfn.CHISQ.INV.RT(0.975,B4-1)-(B4-1)*F4/_xlfn.CHISQ.INV.RT(0.025,B4-1) -> 10.463493 | M4: =(B4-1)*F4/_xlfn.CHISQ.INV.RT(0.025,B4-1) -> 4.8125096 | N4: =(B4-1)*F4/_xlfn.CHISQ.INV.RT(0.975,B4-1) -> 15.276002
A5: 3 Выборка (n = 50) | B5: 50 | C5: =AVERAGE(Подвыборки!L:L) -> 8.34 | D5: =MEDIAN(Подвыборки!N:N) -> 8 | E5: =_xlfn.MODE.SNGL(Подвыборки!L:L) -> 8 | F5: =_xlfn.VAR.S(Подвыборки!L:L) -> 11.249388 | G5: =SQRT(F5) -> 3.3540107 | H5: =_xlfn.STDEV.S(Подвыборки!L:L)/SQRT(Статистики!B5) -> 0.47432874 | I5: =_xlfn.CONFIDENCE.T(0.05,_xlfn.STDEV.S(Подвыборки!L:L),Статистики!B5) -> 0.95319929 | J5: =C5-I5 -> 7.3868007 | K5: =C5+I5 -> 9.2931993 | L5: =(B5-1)*F5/_xlfn.CHISQ.INV.RT(0.975,B5-1)-(B5-1)*F5/_xlfn.CHISQ.INV.RT(0.025,B5-1) -> 9.6189627 | M5: =(B5-1)*F5/_xlfn.CHISQ.INV.RT(0.025,B5-1) -> 7.8496305 | N5: =(B5-1)*F5/_xlfn.CHISQ.INV.RT(0.975,B5-1) -> 17.468593
A6: 4 Выборка (n = 100) | B6: 100 | C6: =AVERAGE(Подвыборки!Q:Q) -> 7.84 | D6: =MEDIAN(Подвыборки!S:S) -> 8 | E6: =_xlfn.MODE.SNGL(Подвыборки!Q:Q) -> 8 | F6: =_xlfn.VAR.S(Подвыборки!Q:Q) -> 8.2367677 | G6: =SQRT(F6) -> 2.8699769 | H6: =_xlfn.STDEV.S(Подвыборки!Q:Q)/SQRT(Статистики!B6) -> 0.28699769 | I6: =_xlfn.CONFIDENCE.T(0.05,_xlfn.STDEV.S(Подвыборки!Q:Q),Статистики!B6) -> 0.56946569 | J6: =C6-I6 -> 7.2705343 | K6: =C6+I6 -> 8.4094657 | L6: =(B6-1)*F6/_xlfn.CHISQ.INV.RT(0.975,B6-1)-(B6-1)*F6/_xlfn.CHISQ.INV.RT(0.025,B6-1) -> 4.7657392 | M6: =(B6-1)*F6/_xlfn.CHISQ.INV.RT(0.025,B6-1) -> 6.3496914 | N6: =(B6-1)*F6/_xlfn.CHISQ.INV.RT(0.975,B6-1) -> 11.115431
A7: 5 Выборка (n = 200) | B7: 200 | C7: =AVERAGE(Подвыборки!V:V) -> 8.045 | D7: =MEDIAN(Подвыборки!X:X) -> 8 | E7: =_xlfn.MODE.SNGL(Подвыборки!V:V) -> 6 | F7: =_xlfn.VAR.S(Подвыборки!V:V) -> 8.5859045 | G7: =SQRT(F7) -> 2.9301714 | H7: =_xlfn.STDEV.S(Подвыборки!V:V)/SQRT(Статистики!B7) -> 0.20719441 | I7: =_xlfn.CONFIDENCE.T(0.05,_xlfn.STDEV.S(Подвыборки!V:V),Статистики!B7) -> 0.40857837 | J7: =C7-I7 -> 7.6364216 | K7: =C7+I7 -> 8.4535784 | L7: =(B7-1)*F7/_xlfn.CHISQ.INV.RT(0.975,B7-1)-(B7-1)*F7/_xlfn.CHISQ.INV.RT(0.025,B7-1) -> 3.4378691 | M7: =(B7-1)*F7/_xlfn.CHISQ.INV.RT(0.025,B7-1) -> 7.120342 | N7: =(B7-1)*F7/_xlfn.CHISQ.INV.RT(0.975,B7-1) -> 10.558211
I8: половина интервала
